Workbook

Sheet Poultry Model
A1: 35,000-BIRD COMMERCIAL POULTRY OPERATION
A2: Medium-Density Production — Sahel Integration
A4: FLOCK COMPOSITION | B4: Value | C4: Unit | D4: Notes
A5: Total annual throughput | B5: 35000 | C5: birds/yr | D5: Target flock size
A6: Broilers (meat birds) | B6: 25000 | C6: birds/yr | D6: 71% of flock — primary meat production
A7: Layers (egg production) | B7: 5000 | C7: birds | D7: Standing flock — replaced every 18 months
A8: Guinea fowl | B8: 3000 | C8: birds/yr | D8: Premium local breed, semi-free-range
A9: Ducks (rice paddy integration) | B9: 2000 | C9: birds/yr | D9: Dual-purpose: eggs + meat
A10: Flock composition check | B10: =B6+B8+B9+B7 -> 35000 | C10: birds | D10: Should approximate total annual target
A12: BROILER PRODUCTION
A13: Birds per batch | B13: =ROUNDUP(B6/B17,0) -> 5000 | C13: birds | D13: Sized to hit annual target
A14: Grow-out period | B14: 49 | C14: days | D14: 7 weeks — standard broiler cycle
A15: Downtime between batches | B15: 14 | C15: days | D15: Clean-out, disinfect, rest
A16: Total cycle length | B16: =B14+B15 -> 63 | C16: days | D16: Grow + turnaround
A17: Batches per year | B17: =ROUNDDOWN(365/B16,0) -> 5 | C17: batches/yr | D17: How many cycles fit in a year
A18: Mortality rate | B18: 0.05 | D18: 5% — good for Sahel conditions
A19: Birds harvested per batch | B19: =B13*(1-B18) -> 4750 | C19: birds | D19: After mortality
A20: Total broilers harvested/year | B20: =B19*B17 -> 23750 | C20: birds/yr | D20: Annual saleable output
A21: Average live weight at harvest | B21: 2 | C21: kg | D21: 7-week broiler in Sahel heat
A22: Dressed weight (75% of live) | B22: =B21*0.75 -> 1.5 | C22: kg | D22: After slaughter and cleaning
A23: Total meat produced (tonnes) | B23: =B20*B22/1000 -> 35.625 | C23: tonnes/yr | D23: Annual dressed weight output
A24: Stocking density | B24: 10 | C24: birds/m² | D24: Medium density — good welfare + performance
A25: Floor space needed per batch | B25: =B13/B24 -> 500 | C25: m² | D25: Active housing area
A27: LAYER PRODUCTION
A28: Standing layer flock | B28: =B7 -> 5000 | C28: birds | D28: Maintained continuously
A29: Lay rate (avg over cycle) | B29: 0.7 | D29: 70% — tropical breed average
A30: Eggs per hen per year | B30: =B29*365 -> 255.5 | C30: eggs/hen/yr | D30: Annual lay rate
A31: Total eggs per year | B31: =B28*B30 -> 1277500 | C31: eggs/yr | D31: Gross production
A32: Eggs lost / broken (5%) | B32: =B31*0.05 -> 63875 | C32: eggs/yr | D32: Handling and storage losses
A33: Saleable eggs per year | B33: =B31-B32 -> 1213625 | C33: eggs/yr | D33: Net marketable eggs
A34: Eggs per month | B34: =B33/12 -> 101135.42 | C34: eggs/month | D34: Average monthly supply
A35: Trays (30 eggs each) per month | B35: =B34/30 -> 3371.1806 | C35: trays/month | D35: Standard market unit
A36: Layer replacement cycle | B36: 18 | C36: months | D36: Hens replaced after peak production
A37: Replacement hens needed/year | B37: =ROUNDUP(B28*12/B36,0) -> 3334 | C37: hens/yr | D37: Rolling replacement
A38: Spent hen value (meat) | B38: 2.5 | C38: $/bird | D38: Sold for stewing/soup — never wasted
A39: Layer housing density | B39: 6 | C39: birds/m² | D39: Lower density than broilers for welfare
A40: Layer floor space needed | B40: =B28/B39 -> 833.33333 | C40: m² | D40: Dedicated layer house
A42: GUINEA FOWL & DUCKS
A43: Guinea fowl annual production | B43: =B8 -> 3000 | C43: birds | D43: Semi-free-range, 12-14 week cycle
A44: Guinea fowl avg weight | B44: 1.5 | C44: kg | D44: Smaller but premium price
...

Sheet Capital Investment
A1: POULTRY INFRASTRUCTURE — CAPITAL INVESTMENT
A2: Medium-Density Commercial Operation (35,000 birds/year)
A4: HOUSING | B4: Cost ($) | C4: Qty | D4: Specification & Notes
A5: Broiler house — Type A (main) | B5: 18000 | C5: 2 | D5: 600 m² each (25m×24m), open-sided with curtains, concrete floor, steel truss roof, holds 3,000 birds at 10/m²
A6: Broiler house — Type B (secondary) | B6: 12000 | C6: 1 | D6: 400 m² (20m×20m), same spec, overflow capacity for batch overlap
A7: Layer house | B7: 15000 | C7: 1 | D7: ~830 m² for 5,000 birds at 6/m², deep litter system, nest boxes, perches
A8: Guinea fowl shelter | B8: 5000 | C8: 2 | D8: Open-sided night shelters, 150 m² each — birds free-range by day
A9: Duck shelter + pond access | B9: 3000 | C9: 1 | D9: Simple shelter near rice paddies + pond, 100 m²
A10: Quarantine / sick bay | B10: 2000 | C10: 1 | D10: Isolated 50 m² unit for new arrivals and sick birds
A11: Feed storage barn | B11: 8000 | C11: 1 | D11: Rodent-proof, ventilated, 100 m², 3-month feed capacity
A12: Egg storage & grading room | B12: 4000 | C12: 1 | D12: Cool room (part of processing shed), grading table, packaging
A13: Slaughter & processing area | B13: 12000 | C13: 1 | D13: 150 m², scalding tank, plucking machine, chill room, drain system
A14: Subtotal Housing | B14: =SUM(B5:B13) -> 79000
A16: EQUIPMENT
A17: Tube feeders (broiler houses) | B17: 3000 | C17: 200 | D17: 1 per 25-30 birds, $15 each
A18: Bell drinkers / nipple lines | B18: 4000 | C18: — | D18: Nipple drinkers preferred — less waste, cleaner water
A19: Layer nest boxes | B19: 2500 | C19: 250 | D19: 1 nest per 4-5 hens, can be locally fabricated
A20: Brooders (gas/electric) | B20: 3000 | C20: 12 | D20: Hover brooders for chick heating, 250 chicks each
A21: Fans / ventilation | B21: 4000 | C21: — | D21: Critical in Sahel heat — ceiling + tunnel ventilation
A22: Egg trays & crates | B22: 1000 | C22: — | D22: Reusable plastic trays
A23: Plucking machine (rotary) | B23: 2500 | C23: 1 | D23: Processes 100+ birds/hour
A24: Scalding tank | B24: 800 | C24: 1 | D24: Thermostatically controlled, 20-bird capacity
A25: Killing cones | B25: 200 | C25: 10 | D25: Stainless steel, wall-mounted
A26: Weighing scales | B26: 500 | C26: 3 | D26: Platform + hanging scales
A27: Cold room (poultry dedicated) | B27: 8000 | C27: 1 | D27: Walk-in, 4°C, solar-powered, 200 bird capacity
A28: Generator backup (poultry) | B28: 3000 | C28: 1 | D28: Dedicated backup for ventilation + cold chain
A29: Biosecurity equipment | B29: 1500 | C29: — | D29: Foot baths, sprayers, PPE, signage
A30: Subtotal Equipment | B30: =SUM(B17:B29) -> 34000
A32: SITE & INFRASTRUCTURE
A33: Site clearing and grading (2 ha) | B33: 3000 | C33: — | D33: Poultry zone site preparation
A34: Perimeter fencing + biosecurity | B34: 5000 | C34: — | D34: Predator-proof, disease barrier
A35: Internal roads / hardstanding | B35: 3000 | C35: — | D35: All-weather access for feed delivery and transport
A36: Water supply (bore/tank + piping) | B36: 4000 | C36: — | D36: Dedicated poultry water — ~3,000 liters/day
A37: Manure composting area | B37: 2000 | C37: — | D37: Concrete pad + covered storage, 200 m²
A38: Solar extension for poultry | B38: 8000 | C38: — | D38: ~5 kWp for fans, lights, cold room — on poultry shed roof
A39: Subtotal Site | B39: =SUM(B33:B38) -> 25000
A41: INITIAL LIVESTOCK
A42: Day-old chicks (first 2 batches) | B42: =B5*2*0.6*2 -> 43200 | C42: — | D42: First 2 batches at $0.60/DOC — pipeline fill
A43: Point-of-lay pullets (layers) | B43: =B28*5 -> 15000 | C43: — | D43: 5,000 pullets at $5 each — one-time
A44: Guinea fowl keets (founding) | B44: =1000*0.8 -> 800 | C44: — | D44: 1,000 keets for first batch + breeding stock
...

Sheet Farm Impact
A1: IMPACT ON TOTAL FARM ANNUAL INCOME
B3: Before (Original) | C3: After (35k Poultry) | D3: Change
A4: REVENUE
A5: Tilapia operations | B5: 519000 | C5: 519000 | D5: =C5-B5 -> 0
A6: Poultry (chicken, guinea, duck) | B6: 45000 | C6: ='Poultry Model'!B76 -> 392971.25 | D6: =C6-B6 -> 347971.25
A7: Sheep | B7: 40000 | C7: 40000 | D7: =C7-B7 -> 0
A8: Crop operations | B8: 281000 | C8: 281000 | D8: =C8-B8 -> 0
A9: Processed products | B9: 133000 | C9: 133000 | D9: =C9-B9 -> 0
A10: Processing fees | B10: 90000 | C10: 90000 | D10: =C10-B10 -> 0
A11: TOTAL REVENUE | B11: =SUM(B5:B10) -> 1108000 | C11: =SUM(C5:C10) -> 1455971.2 | D11: =C11-B11 -> 347971.25
A13: OPERATING COSTS
A14: Previous total costs | B14: 363636 | C14: 363636 | D14: =C14-B14 -> 0
A15: Remove old poultry costs | B15: 0 | C15: -30000 | D15: =C15-B15 -> -30000
A16: Add new poultry feed cost | B16: 0 | C16: ='Poultry Model'!B92 -> 162112.5 | D16: =C16-B16 -> 162112.5
A17: Add new poultry operating costs | B17: 0 | C17: ='Poultry Model'!B107 -> 73220 | D17: =C17-B17 -> 73220
A18: TOTAL OPERATING COSTS | B18: =SUM(B14:B17) -> 363636 | C18: =SUM(C14:C17) -> 568968.5 | D18: =C18-B18 -> 205332.5
A20: NET ANNUAL PROFIT | B20: =B11-B18 -> 744364 | C20: =C11-C18 -> 887002.75 | D20: =C20-B20 -> 142638.75
A21: Monthly Revenue | B21: =B11/12 -> 92333.333 | C21: =C11/12 -> 121330.94 | D21: =C21-B21 -> 28997.604
A22: Monthly Profit | B22: =B20/12 -> 62030.333 | C22: =C20/12 -> 73916.896 | D22: =C22-B22 -> 11886.562
A23: Operating Margin | B23: =B20/B11 -> 0.67180866 | C23: =C20/C11 -> 0.60921721 | D23: =C23-B23 -> -0.062591449
A25: KEY IMPACT METRICS
A26: Revenue increase ($) | B26: =C11-B11 -> 347971.25
A27: Revenue increase (%) | B27: =(C11-B11)/B11 -> 0.31405347
A28: Profit increase ($) | B28: =C20-B20 -> 142638.75
A29: Profit increase (%) | B29: =(C20-B20)/B20 -> 0.191625
A30: New monthly revenue | B30: =C11/12 -> 121330.94
A31: New monthly profit | B31: =C20/12 -> 73916.896
A32: Poultry as % of new revenue | B32: =C6/C11 -> 0.26990317
A33: Additional CapEx required | B33: ='Capital Investment'!B50 -> 216975
A34: CapEx payback from incremental profit | B34: =B33/(C20-B20) -> 1.5211505 | C34: years
