Workbook

Sheet Assumptions
A1: INTEGRATED SAHEL FARM — FINANCIAL MODEL
A2: Key Assumptions & Parameters
A4: TILAPIA TANK PARAMETERS | B4: Value | C4: Unit | D4: Notes
A5: Number of tanks | B5: 15 | C5: tanks | D5: Ferrocement, 5m diameter × 1.8m deep
A6: Fish per tank (stocking) | B6: 2000 | C6: fingerlings | D6: 50-60 fish/m³ at harvest
A7: Tank volume | B7: 35 | C7: m³ | D7: ~35 m³ per tank
A8: Grow-out cycle | B8: 6 | C8: months | D8: Stocking to harvest
A9: Survival rate | B9: 0.85 | D9: 85% typical for intensive tanks
A10: Harvest weight (avg) | B10: 0.375 | C10: kg/fish | D10: 350-400g target
A11: Feed conversion ratio (FCR) | B11: 1.6 | C11: kg feed/kg fish | D11: Intensive tank FCR
A12: On-farm feed substitution | B12: 0.3 | D12: 30% replaced by farm ingredients
A13: Commercial feed cost | B13: 700 | C13: $/tonne | D13: West Africa avg delivered
A14: Fresh fish price | B14: 3 | C14: $/kg | D14: Wholesale/market price
A15: Smoked/dried fish price | B15: 6 | C15: $/kg | D15: Value-added processing
A16: % sold as processed | B16: 0.2 | D16: 20% smoked/dried
A17: Fingerling cost | B17: 0.05 | C17: $/fingerling | D17: After own breeding established
A18: Tanks harvested per month | B18: 2.5 | C18: tanks/month | D18: Staggered 6-month cycle
A20: CALCULATED TILAPIA METRICS
A21: Fish harvested per tank | B21: =B5*B9 -> 12.75 | C21: fish | D21: Stocked × survival rate
A22: Fish harvested per month | B22: =B21*B18 -> 31.875 | C22: fish | D22: Per tank × tanks/month
A23: Annual fish harvested | B23: =B22*12 -> 382.5 | C23: fish | D23: Monthly × 12 (once pipeline full)
A24: Annual fish weight (tonnes) | B24: =B23*B10/1000 -> 0.1434375 | C24: tonnes | D24: Fish × avg weight
A25: Annual feed required (tonnes) | B25: =B24*B11 -> 0.2295 | C25: tonnes | D25: Fish weight × FCR
A26: Commercial feed needed (tonnes) | B26: =B25*(1-B12) -> 0.16065 | C26: tonnes | D26: After on-farm substitution
A27: Annual feed cost | B27: =B26*B13 -> 112.455 | C27: $ | D27: Commercial feed × price
A28: Revenue: fresh fish | B28: =B24*1000*(1-B16)*B14 -> 344.25 | C28: $ | D28: 80% sold fresh
A29: Revenue: processed fish | B29: =B24*1000*B16*B15 -> 172.125 | C29: $ | D29: 20% smoked/dried
A30: Total fish revenue | B30: =B28+B29 -> 516.375 | C30: $ | D30: Combined fish sales
A31: Fingerling sales revenue | B31: 3000 | C31: $ | D31: Surplus fingerlings to other farms
A32: Gross fish revenue | B32: =B30+B31 -> 3516.375 | C32: $ | D32: All fish income streams
A34: OTHER FARM REVENUE (ANNUAL)
A35: Potatoes (fresh + processed) | B35: 14000 | D35: Peak: Nov-Mar (dry season harvest)
A36: Onions (stored, off-season sales) | B36: 10000 | D36: Peak: Apr-Jul (off-season premium)
A37: Rice | B37: 3500 | D37: Peak: Oct-Dec (wet season harvest)
A38: Cowpeas / Bambara groundnut | B38: 4500 | D38: Peak: Oct-Nov
A39: Eggs (chicken + duck) | B39: 3000 | D39: Year-round, steady
A40: Poultry meat (chicken + guinea fowl) | B40: 4000 | D40: Year-round, slight holiday peaks
A41: Sheep (Tabaski lambs) | B41: 7500 | D41: Highly seasonal: Tabaski month
A42: Pork (if applicable) | B42: 3000 | D42: Year-round
A43: Fruit / cashews / mangoes | B43: 5500 | D43: Seasonal: Mar-Jul
...

Sheet Monthly Cash Flow
A1: MONTHLY CASH FLOW — YEAR 2 (Full Operations)
A3: REVENUE | B3: Jan | C3: Feb | D3: Mar | E3: Apr | F3: May | G3: Jun | H3: Jul | I3: Aug | J3: Sep | K3: Oct | L3: Nov | M3: Dec | N3: TOTAL
A4: Tilapia (fresh + processed) | B4: =Assumptions!B30*0.083 -> 42.859125 | C4: =Assumptions!B30*0.083 -> 42.859125 | D4: =Assumptions!B30*0.083 -> 42.859125 | E4: =Assumptions!B30*0.083 -> 42.859125 | F4: =Assumptions!B30*0.083 -> 42.859125 | G4: =Assumptions!B30*0.083 -> 42.859125 | H4: =Assumptions!B30*0.083 -> 42.859125 | I4: =Assumptions!B30*0.083 -> 42.859125 | J4: =Assumptions!B30*0.083 -> 42.859125 | K4: =Assumptions!B30*0.083 -> 42.859125 | L4: =Assumptions!B30*0.083 -> 42.859125 | M4: =Assumptions!B30*0.087 -> 44.924625 | N4: =B4+C4+D4+E4+F4+G4+H4+I4+J4+K4+L4+M4 -> 516.375
A5: Fingerling sales | B5: =Assumptions!B31*0.05 -> 150 | C5: =Assumptions!B31*0.05 -> 150 | D5: =Assumptions!B31*0.08 -> 240 | E5: =Assumptions!B31*0.1 -> 300 | F5: =Assumptions!B31*0.1 -> 300 | G5: =Assumptions!B31*0.12 -> 360 | H5: =Assumptions!B31*0.12 -> 360 | I5: =Assumptions!B31*0.1 -> 300 | J5: =Assumptions!B31*0.1 -> 300 | K5: =Assumptions!B31*0.08 -> 240 | L5: =Assumptions!B31*0.05 -> 150 | M5: =Assumptions!B31*0.05 -> 150 | N5: =B5+C5+D5+E5+F5+G5+H5+I5+J5+K5+L5+M5 -> 3000
A6: Potatoes | B6: =Assumptions!B35*0.15 -> 2100 | C6: =Assumptions!B35*0.15 -> 2100 | D6: =Assumptions!B35*0.12 -> 1680 | E6: =Assumptions!B35*0.05 -> 700 | F6: =Assumptions!B35*0.03 -> 420 | G6: =Assumptions!B35*0 -> 0 | H6: =Assumptions!B35*0 -> 0 | I6: =Assumptions!B35*0 -> 0 | J6: =Assumptions!B35*0 -> 0 | K6: =Assumptions!B35*0.05 -> 700 | L6: =Assumptions!B35*0.2 -> 2800 | M6: =Assumptions!B35*0.25 -> 3500 | N6: =B6+C6+D6+E6+F6+G6+H6+I6+J6+K6+L6+M6 -> 14000
A7: Onions | B7: =Assumptions!B36*0.05 -> 500 | C7: =Assumptions!B36*0.05 -> 500 | D7: =Assumptions!B36*0.08 -> 800 | E7: =Assumptions!B36*0.15 -> 1500 | F7: =Assumptions!B36*0.2 -> 2000 | G7: =Assumptions!B36*0.2 -> 2000 | H7: =Assumptions!B36*0.12 -> 1200 | I7: =Assumptions!B36*0.05 -> 500 | J7: =Assumptions!B36*0.02 -> 200 | K7: =Assumptions!B36*0.02 -> 200 | L7: =Assumptions!B36*0.03 -> 300 | M7: =Assumptions!B36*0.03 -> 300 | N7: =B7+C7+D7+E7+F7+G7+H7+I7+J7+K7+L7+M7 -> 10000
A8: Rice | B8: =Assumptions!B37*0.02 -> 70 | C8: =Assumptions!B37*0.02 -> 70 | D8: =Assumptions!B37*0.02 -> 70 | E8: =Assumptions!B37*0.02 -> 70 | F8: =Assumptions!B37*0.02 -> 70 | G8: =Assumptions!B37*0.02 -> 70 | H8: =Assumptions!B37*0.05 -> 175 | I8: =Assumptions!B37*0.05 -> 175 | J8: =Assumptions!B37*0.1 -> 350 | K8: =Assumptions!B37*0.25 -> 875 | L8: =Assumptions!B37*0.25 -> 875 | M8: =Assumptions!B37*0.18 -> 630 | N8: =B8+C8+D8+E8+F8+G8+H8+I8+J8+K8+L8+M8 -> 3500
A9: Cowpeas / Bambara | B9: =Assumptions!B38*0.03 -> 135 | C9: =Assumptions!B38*0.03 -> 135 | D9: =Assumptions!B38*0.03 -> 135 | E9: =Assumptions!B38*0.03 -> 135 | F9: =Assumptions!B38*0.03 -> 135 | G9: =Assumptions!B38*0.05 -> 225 | H9: =Assumptions!B38*0.05 -> 225 | I9: =Assumptions!B38*0.08 -> 360 | J9: =Assumptions!B38*0.12 -> 540 | K9: =Assumptions!B38*0.2 -> 900 | L9: =Assumptions!B38*0.2 -> 900 | M9: =Assumptions!B38*0.15 -> 675 | N9: =B9+C9+D9+E9+F9+G9+H9+I9+J9+K9+L9+M9 -> 4500
A10: Eggs | B10: =Assumptions!B39*0.083 -> 249 | C10: =Assumptions!B39*0.083 -> 249 | D10: =Assumptions!B39*0.083 -> 249 | E10: =Assumptions!B39*0.083 -> 249 | F10: =Assumptions!B39*0.083 -> 249 | G10: =Assumptions!B39*0.083 -> 249 | H10: =Assumptions!B39*0.083 -> 249 | I10: =Assumptions!B39*0.083 -> 249 | J10: =Assumptions!B39*0.083 -> 249 | K10: =Assumptions!B39*0.083 -> 249 | L10: =Assumptions!B39*0.083 -> 249 | M10: =Assumptions!B39*0.087 -> 261 | N10: =B10+C10+D10+E10+F10+G10+H10+I10+J10+K10+L10+M10 -> 3000
A11: Poultry meat | B11: =Assumptions!B40*0.08 -> 320 | C11: =Assumptions!B40*0.08 -> 320 | D11: =Assumptions!B40*0.08 -> 320 | E11: =Assumptions!B40*0.07 -> 280 | F11: =Assumptions!B40*0.07 -> 280 | G11: =Assumptions!B40*0.07 -> 280 | H11: =Assumptions!B40*0.07 -> 280 | I11: =Assumptions!B40*0.07 -> 280 | J11: =Assumptions!B40*0.08 -> 320 | K11: =Assumptions!B40*0.08 -> 320 | L11: =Assumptions!B40*0.12 -> 480 | M11: =Assumptions!B40*0.13 -> 520 | N11: =B11+C11+D11+E11+F11+G11+H11+I11+J11+K11+L11+M11 -> 4000
A12: Sheep (Tabaski) | B12: 0 | C12: 0 | D12: 0 | E12: 0 | F12: 0 | G12: =Assumptions!B41 -> 7500 | H12: 0 | I12: 0 | J12: 0 | K12: 0 | L12: 0 | M12: 0 | N12: =B12+C12+D12+E12+F12+G12+H12+I12+J12+K12+L12+M12 -> 7500
A13: Pork | B13: =Assumptions!B42*0.08 -> 240 | C13: =Assumptions!B42*0.08 -> 240 | D13: =Assumptions!B42*0.08 -> 240 | E13: =Assumptions!B42*0.08 -> 240 | F13: =Assumptions!B42*0.08 -> 240 | G13: =Assumptions!B42*0.08 -> 240 | H13: =Assumptions!B42*0.08 -> 240 | I13: =Assumptions!B42*0.08 -> 240 | J13: =Assumptions!B42*0.09 -> 270 | K13: =Assumptions!B42*0.09 -> 270 | L13: =Assumptions!B42*0.09 -> 270 | M13: =Assumptions!B42*0.09 -> 270 | N13: =B13+C13+D13+E13+F13+G13+H13+I13+J13+K13+L13+M13 -> 3000
A14: Fruit / cashews | B14: =Assumptions!B43*0.02 -> 110 | C14: =Assumptions!B43*0.02 -> 110 | D14: =Assumptions!B43*0.1 -> 550 | E14: =Assumptions!B43*0.18 -> 990 | F14: =Assumptions!B43*0.22 -> 1210 | G14: =Assumptions!B43*0.2 -> 1100 | H14: =Assumptions!B43*0.15 -> 825 | I14: =Assumptions!B43*0.05 -> 275 | J14: =Assumptions!B43*0.02 -> 110 | K14: =Assumptions!B43*0.01 -> 55 | L14: =Assumptions!B43*0.01 -> 55 | M14: =Assumptions!B43*0.02 -> 110 | N14: =B14+C14+D14+E14+F14+G14+H14+I14+J14+K14+L14+M14 -> 5500
A15: Moringa | B15: =Assumptions!B44*0.1 -> 350 | C15: =Assumptions!B44*0.1 -> 350 | D15: =Assumptions!B44*0.1 -> 350 | E15: =Assumptions!B44*0.08 -> 280 | F15: =Assumptions!B44*0.06 -> 210 | G15: =Assumptions!B44*0.05 -> 175 | H15: =Assumptions!B44*0.05 -> 175 | I15: =Assumptions!B44*0.06 -> 210 | J15: =Assumptions!B44*0.08 -> 280 | K15: =Assumptions!B44*0.1 -> 350 | L15: =Assumptions!B44*0.11 -> 385 | M15: =Assumptions!B44*0.11 -> 385 | N15: =B15+C15+D15+E15+F15+G15+H15+I15+J15+K15+L15+M15 -> 3500
A16: Dried products | B16: =Assumptions!B45*0.08 -> 360 | C16: =Assumptions!B45*0.08 -> 360 | D16: =Assumptions!B45*0.09 -> 405 | E16: =Assumptions!B45*0.09 -> 405 | F16: =Assumptions!B45*0.09 -> 405 | G16: =Assumptions!B45*0.07 -> 315 | H16: =Assumptions!B45*0.06 -> 270 | I16: =Assumptions!B45*0.07 -> 315 | J16: =Assumptions!B45*0.08 -> 360 | K16: =Assumptions!B45*0.09 -> 405 | L16: =Assumptions!B45*0.1 -> 450 | M16: =Assumptions!B45*0.1 -> 450 | N16: =B16+C16+D16+E16+F16+G16+H16+I16+J16+K16+L16+M16 -> 4500
A17: Peanuts | B17: =Assumptions!B46*0.03 -> 60 | C17: =Assumptions!B46*0.03 -> 60 | D17: =Assumptions!B46*0.03 -> 60 | E17: =Assumptions!B46*0.03 -> 60 | F17: =Assumptions!B46*0.03 -> 60 | G17: =Assumptions!B46*0.03 -> 60 | H17: =Assumptions!B46*0.05 -> 100 | I17: =Assumptions!B46*0.08 -> 160 | J17: =Assumptions!B46*0.15 -> 300 | K17: =Assumptions!B46*0.22 -> 440 | L17: =Assumptions!B46*0.2 -> 400 | M17: =Assumptions!B46*0.12 -> 240 | N17: =B17+C17+D17+E17+F17+G17+H17+I17+J17+K17+L17+M17 -> 2000
A18: Processing fees | B18: =Assumptions!B47*0.06 -> 270 | C18: =Assumptions!B47*0.06 -> 270 | D18: =Assumptions!B47*0.08 -> 360 | E18: =Assumptions!B47*0.08 -> 360 | F18: =Assumptions!B47*0.08 -> 360 | G18: =Assumptions!B47*0.05 -> 225 | H18: =Assumptions!B47*0.05 -> 225 | I18: =Assumptions!B47*0.06 -> 270 | J18: =Assumptions!B47*0.08 -> 360 | K18: =Assumptions!B47*0.12 -> 540 | L18: =Assumptions!B47*0.15 -> 675 | M18: =Assumptions!B47*0.13 -> 585 | N18: =B18+C18+D18+E18+F18+G18+H18+I18+J18+K18+L18+M18 -> 4500
A19: TOTAL REVENUE | B19: =SUM(B4:B18) -> 4956.8591 | C19: =SUM(C4:C18) -> 4956.8591 | D19: =SUM(D4:D18) -> 5501.8591 | E19: =SUM(E4:E18) -> 5611.8591 | F19: =SUM(F4:F18) -> 5981.8591 | G19: =SUM(G4:G18) -> 12841.859 | H19: =SUM(H4:H18) -> 4366.8591 | I19: =SUM(I4:I18) -> 3376.8591 | ... N19: =SUM(N4:N18) -> 73016.375
A21: OPERATING COSTS | B21: Jan | C21: Feb | D21: Mar | E21: Apr | F21: May | G21: Jun | H21: Jul | I21: Aug | J21: Sep | K21: Oct | L21: Nov | M21: Dec | N21: TOTAL
A22: Labor | B22: =Assumptions!B51*0.083 -> 1494 | C22: =Assumptions!B51*0.083 -> 1494 | D22: =Assumptions!B51*0.083 -> 1494 | E22: =Assumptions!B51*0.083 -> 1494 | F22: =Assumptions!B51*0.083 -> 1494 | G22: =Assumptions!B51*0.083 -> 1494 | H22: =Assumptions!B51*0.083 -> 1494 | I22: =Assumptions!B51*0.083 -> 1494 | J22: =Assumptions!B51*0.083 -> 1494 | K22: =Assumptions!B51*0.083 -> 1494 | L22: =Assumptions!B51*0.083 -> 1494 | M22: =Assumptions!B51*0.087 -> 1566 | N22: =B22+C22+D22+E22+F22+G22+H22+I22+J22+K22+L22+M22 -> 18000
A23: Fish feed | B23: =Assumptions!B52*0.083 -> 9.333765 | C23: =Assumptions!B52*0.083 -> 9.333765 | D23: =Assumptions!B52*0.083 -> 9.333765 | E23: =Assumptions!B52*0.083 -> 9.333765 | F23: =Assumptions!B52*0.083 -> 9.333765 | G23: =Assumptions!B52*0.083 -> 9.333765 | H23: =Assumptions!B52*0.083 -> 9.333765 | I23: =Assumptions!B52*0.083 -> 9.333765 | J23: =Assumptions!B52*0.083 -> 9.333765 | K23: =Assumptions!B52*0.083 -> 9.333765 | L23: =Assumptions!B52*0.083 -> 9.333765 | M23: =Assumptions!B52*0.087 -> 9.783585 | N23: =B23+C23+D23+E23+F23+G23+H23+I23+J23+K23+L23+M23 -> 112.455
A24: Seeds & inputs | B24: =Assumptions!B53*0.05 -> 325 | C24: =Assumptions!B53*0.05 -> 325 | D24: =Assumptions!B53*0.08 -> 520 | E24: =Assumptions!B53*0.05 -> 325 | F24: =Assumptions!B53*0.05 -> 325 | G24: =Assumptions!B53*0.08 -> 520 | H24: =Assumptions!B53*0.08 -> 520 | I24: =Assumptions!B53*0.12 -> 780 | J24: =Assumptions!B53*0.15 -> 975 | K24: =Assumptions!B53*0.12 -> 780 | L24: =Assumptions!B53*0.1 -> 650 | M24: =Assumptions!B53*0.07 -> 455 | N24: =B24+C24+D24+E24+F24+G24+H24+I24+J24+K24+L24+M24 -> 6500
A25: Animal feed supplements | B25: =Assumptions!B54*0.08 -> 240 | C25: =Assumptions!B54*0.08 -> 240 | D25: =Assumptions!B54*0.08 -> 240 | E25: =Assumptions!B54*0.08 -> 240 | F25: =Assumptions!B54*0.08 -> 240 | G25: =Assumptions!B54*0.08 -> 240 | H25: =Assumptions!B54*0.08 -> 240 | I25: =Assumptions!B54*0.09 -> 270 | J25: =Assumptions!B54*0.09 -> 270 | K25: =Assumptions!B54*0.09 -> 270 | L25: =Assumptions!B54*0.09 -> 270 | M25: =Assumptions!B54*0.08 -> 240 | N25: =B25+C25+D25+E25+F25+G25+H25+I25+J25+K25+L25+M25 -> 3000
A26: Veterinary | B26: =Assumptions!B55*0.08 -> 120 | C26: =Assumptions!B55*0.08 -> 120 | D26: =Assumptions!B55*0.08 -> 120 | E26: =Assumptions!B55*0.08 -> 120 | F26: =Assumptions!B55*0.08 -> 120 | G26: =Assumptions!B55*0.08 -> 120 | H26: =Assumptions!B55*0.09 -> 135 | I26: =Assumptions!B55*0.09 -> 135 | J26: =Assumptions!B55*0.09 -> 135 | K26: =Assumptions!B55*0.09 -> 135 | L26: =Assumptions!B55*0.08 -> 120 | M26: =Assumptions!B55*0.08 -> 120 | N26: =B26+C26+D26+E26+F26+G26+H26+I26+J26+K26+L26+M26 -> 1500
A27: Equipment maintenance | B27: =Assumptions!B56*0.08 -> 240 | C27: =Assumptions!B56*0.08 -> 240 | D27: =Assumptions!B56*0.08 -> 240 | E27: =Assumptions!B56*0.08 -> 240 | F27: =Assumptions!B56*0.08 -> 240 | G27: =Assumptions!B56*0.08 -> 240 | H27: =Assumptions!B56*0.09 -> 270 | I27: =Assumptions!B56*0.09 -> 270 | J27: =Assumptions!B56*0.09 -> 270 | K27: =Assumptions!B56*0.09 -> 270 | L27: =Assumptions!B56*0.08 -> 240 | M27: =Assumptions!B56*0.08 -> 240 | N27: =B27+C27+D27+E27+F27+G27+H27+I27+J27+K27+L27+M27 -> 3000
A28: Fuel / transport | B28: =Assumptions!B57*0.07 -> 175 | C28: =Assumptions!B57*0.07 -> 175 | D28: =Assumptions!B57*0.08 -> 200 | E28: =Assumptions!B57*0.09 -> 225 | F28: =Assumptions!B57*0.09 -> 225 | G28: =Assumptions!B57*0.08 -> 200 | H28: =Assumptions!B57*0.07 -> 175 | I28: =Assumptions!B57*0.07 -> 175 | J28: =Assumptions!B57*0.08 -> 200 | K28: =Assumptions!B57*0.1 -> 250 | L28: =Assumptions!B57*0.11 -> 275 | M28: =Assumptions!B57*0.09 -> 225 | N28: =B28+C28+D28+E28+F28+G28+H28+I28+J28+K28+L28+M28 -> 2500
A29: Packaging | B29: =Assumptions!B58*0.07 -> 140 | C29: =Assumptions!B58*0.07 -> 140 | D29: =Assumptions!B58*0.08 -> 160 | E29: =Assumptions!B58*0.09 -> 180 | F29: =Assumptions!B58*0.09 -> 180 | G29: =Assumptions!B58*0.08 -> 160 | H29: =Assumptions!B58*0.07 -> 140 | I29: =Assumptions!B58*0.07 -> 140 | J29: =Assumptions!B58*0.08 -> 160 | K29: =Assumptions!B58*0.1 -> 200 | L29: =Assumptions!B58*0.11 -> 220 | M29: =Assumptions!B58*0.09 -> 180 | N29: =B29+C29+D29+E29+F29+G29+H29+I29+J29+K29+L29+M29 -> 2000
A30: Miscellaneous | B30: =Assumptions!B59*0.083 -> 166 | C30: =Assumptions!B59*0.083 -> 166 | D30: =Assumptions!B59*0.083 -> 166 | E30: =Assumptions!B59*0.083 -> 166 | F30: =Assumptions!B59*0.083 -> 166 | G30: =Assumptions!B59*0.083 -> 166 | H30: =Assumptions!B59*0.083 -> 166 | I30: =Assumptions!B59*0.083 -> 166 | J30: =Assumptions!B59*0.083 -> 166 | K30: =Assumptions!B59*0.083 -> 166 | L30: =Assumptions!B59*0.083 -> 166 | M30: =Assumptions!B59*0.087 -> 174 | N30: =B30+C30+D30+E30+F30+G30+H30+I30+J30+K30+L30+M30 -> 2000
A31: TOTAL OPERATING COSTS | B31: =SUM(B22:B30) -> 2909.3338 | C31: =SUM(C22:C30) -> 2909.3338 | D31: =SUM(D22:D30) -> 3149.3338 | E31: =SUM(E22:E30) -> 2999.3338 | F31: =SUM(F22:F30) -> 2999.3338 | G31: =SUM(G22:G30) -> 3149.3338 | H31: =SUM(H22:H30) -> 3149.3338 | I31: =SUM(I22:I30) -> 3439.3338 | ... N31: =SUM(N22:N30) -> 38612.455
A33: NET MONTHLY CASH FLOW | B33: =B19-B31 -> 2047.5254 | C33: =C19-C31 -> 2047.5254 | D33: =D19-D31 -> 2352.5254 | E33: =E19-E31 -> 2612.5254 | F33: =F19-F31 -> 2982.5254 | G33: =G19-G31 -> 9692.5254 | H33: =H19-H31 -> 1217.5254 | I33: =I19-I31 -> -62.47464 | ... N33: =N19-N31 -> 34403.92
A34: CUMULATIVE CASH FLOW | B34: =B33 -> 2047.5254 | C34: =B34+C33 -> 4095.0507 | D34: =C34+D33 -> 6447.5761 | E34: =D34+E33 -> 9060.1014 | F34: =E34+F33 -> 12042.627 | G34: =F34+G33 -> 21735.152 | H34: =G34+H33 -> 22952.678 | I34: =H34+I33 -> 22890.203 | J34: =I34+J33 -> 22892.728 | ... M34: =L34+M33 -> 34403.92 | N34: =M34 -> 34403.92
A36: KEY METRICS
A37: Total Annual Revenue | B37: =N19 -> 73016.375
A38: Total Annual Costs | B38: =N31 -> 38612.455
A39: Annual Net Profit | B39: =N33 -> 34403.92
A40: Operating Margin | B40: =B39/B37 -> 0.47118088
A41: Monthly Avg Revenue | B41: =B37/12 -> 6084.6979
A42: Monthly Avg Net Profit | B42: =B39/12 -> 2866.9933
A43: Fish as % of Revenue | B43: =(N4+N5)/N19 -> 0.048158718
A44: Payback Period (years) | B44: =Assumptions!B80/B39 -> 6.1388353

Sheet 5-Year Projection
A1: 5-YEAR FINANCIAL PROJECTION
A3: GROWTH ASSUMPTIONS | B3: Year 1 | C3: Year 2 | D3: Year 3 | E3: Year 4 | F3: Year 5
A4: Revenue ramp-up factor | B4: 0.4 | C4: 1 | D4: 1.1 | E4: 1.15 | F4: 1.2
A5: Cost ramp-up factor | B5: 0.6 | C5: 1 | D5: 1.05 | E5: 1.08 | F5: 1.1
A7: REVENUE
A8: Fish revenue (base) | B8: =Assumptions!B32*B4 -> 1406.55 | C8: =Assumptions!B32*C4 -> 3516.375 | D8: =Assumptions!B32*D4 -> 3868.0125 | E8: =Assumptions!B32*E4 -> 4043.8313 | F8: =Assumptions!B32*F4 -> 4219.65
A9: Other farm revenue (base) | B9: =Assumptions!B48*B4 -> 27800 | C9: =Assumptions!B48*C4 -> 69500 | D9: =Assumptions!B48*D4 -> 76450 | E9: =Assumptions!B48*E4 -> 79925 | F9: =Assumptions!B48*F4 -> 83400
A10: Total Revenue | B10: =B8+B9 -> 29206.55 | C10: =C8+C9 -> 73016.375 | D10: =D8+D9 -> 80318.012 | E10: =E8+E9 -> 83968.831 | F10: =F8+F9 -> 87619.65
A12: COSTS
A13: Operating costs (base) | B13: =Assumptions!B60*B5 -> 23167.473 | C13: =Assumptions!B60*C5 -> 38612.455 | D13: =Assumptions!B60*D5 -> 40543.078 | E13: =Assumptions!B60*E5 -> 41701.451 | F13: =Assumptions!B60*F5 -> 42473.7
A14: Capital expenditure | B14: 120000 | C14: 50000 | D14: 25000 | E14: 10000 | F14: 5000
A15: Total Costs + CapEx | B15: =B13+B14 -> 143167.47 | C15: =C13+C14 -> 88612.455 | D15: =D13+D14 -> 65543.078 | E15: =E13+E14 -> 51701.451 | F15: =F13+F14 -> 47473.7
A17: NET PROFIT (before CapEx) | B17: =B10-B13 -> 6039.077 | C17: =C10-C13 -> 34403.92 | D17: =D10-D13 -> 39774.935 | E17: =E10-E13 -> 42267.38 | F17: =F10-F13 -> 45145.95
A18: NET CASH FLOW (after CapEx) | B18: =B10-B15 -> -113960.92 | C18: =C10-C15 -> -15596.08 | D18: =D10-D15 -> 14774.935 | E18: =E10-E15 -> 32267.38 | F18: =F10-F15 -> 40145.95
A19: CUMULATIVE CASH FLOW | B19: =B18 -> -113960.92 | C19: =B19+C18 -> -129557 | D19: =C19+D18 -> -114782.07 | E19: =D19+E18 -> -82514.688 | F19: =E19+F18 -> -42368.739
A21: Operating Margin | B21: =B17/B10 -> 0.20677132 | C21: =C17/C10 -> 0.47118088 | D21: =D17/D10 -> 0.49521811 | E21: =E17/E10 -> 0.50336987 | F21: =F17/F10 -> 0.51524914
A22: Revenue per hectare | B22: =B10/25 -> 1168.262 | C22: =C10/25 -> 2920.655 | D22: =D10/25 -> 3212.7205 | E22: =E10/25 -> 3358.7533 | F22: =F10/25 -> 3504.786

Sheet Tank Schedule
A1: TILAPIA TANK STOCKING & HARVEST SCHEDULE
A3: Month | B3: Tank 1 | C3: Tank 2 | D3: Tank 3 | E3: Tank 4 | F3: Tank 5 | G3: Tank 6 | H3: Tank 7 | I3: Tank 8 | J3: Tank 9 | K3: Tank 10 | L3: Tank 11 | M3: Tank 12 | N3: Tank 13 | O3: Tank 14 | P3: Tank 15
A4: Month 1 | B4: STOCK | C4: — | D4: — | E4: — | F4: — | G4: — | H4: — | I4: — | J4: — | K4: — | L4: — | M4: — | N4: — | O4: — | P4: —
A5: Month 2 | B5: Grow-1 | C5: STOCK | D5: — | E5: — | F5: — | G5: — | H5: — | I5: — | J5: — | K5: — | L5: — | M5: — | N5: — | O5: — | P5: —
A6: Month 3 | B6: Grow-2 | C6: Grow-1 | D6: STOCK | E6: — | F6: — | G6: — | H6: — | I6: — | J6: — | K6: — | L6: — | M6: — | N6: — | O6: — | P6: —
A7: Month 4 | B7: Grow-3 | C7: Grow-2 | D7: Grow-1 | E7: STOCK | F7: — | G7: — | H7: — | I7: — | J7: — | K7: — | L7: — | M7: — | N7: — | O7: — | P7: —
A8: Month 5 | B8: Grow-4 | C8: Grow-3 | D8: Grow-2 | E8: Grow-1 | F8: STOCK | G8: — | H8: — | I8: — | J8: — | K8: — | L8: — | M8: — | N8: — | O8: — | P8: —
A9: Month 6 | B9: HARVEST | C9: Grow-4 | D9: Grow-3 | E9: Grow-2 | F9: Grow-1 | G9: STOCK | H9: — | I9: — | J9: — | K9: — | L9: — | M9: — | N9: — | O9: — | P9: —
A10: Month 7 | B10: STOCK | C10: HARVEST | D10: Grow-4 | E10: Grow-3 | F10: Grow-2 | G10: Grow-1 | H10: STOCK | I10: — | J10: — | K10: — | L10: — | M10: — | N10: — | O10: — | P10: —
A11: Month 8 | B11: Grow-1 | C11: STOCK | D11: HARVEST | E11: Grow-4 | F11: Grow-3 | G11: Grow-2 | H11: Grow-1 | I11: STOCK | J11: — | K11: — | L11: — | M11: — | N11: — | O11: — | P11: —
A12: Month 9 | B12: Grow-2 | C12: Grow-1 | D12: STOCK | E12: HARVEST | F12: Grow-4 | G12: Grow-3 | H12: Grow-2 | I12: Grow-1 | J12: — | K12: — | L12: — | M12: — | N12: — | O12: — | P12: —
A13: Month 10 | B13: Grow-3 | C13: Grow-2 | D13: Grow-1 | E13: STOCK | F13: HARVEST | G13: Grow-4 | H13: Grow-3 | I13: Grow-2 | J13: STOCK | K13: — | L13: — | M13: — | N13: — | O13: — | P13: —
A14: Month 11 | B14: Grow-4 | C14: Grow-3 | D14: Grow-2 | E14: Grow-1 | F14: STOCK | G14: HARVEST | H14: Grow-4 | I14: Grow-3 | J14: Grow-1 | K14: STOCK | L14: — | M14: — | N14: — | O14: — | P14: —
... A21: Month 18 | B21: HARVEST | C21: Grow-4 | D21: Grow-3 | E21: Grow-2 | F21: Grow-1 | G21: STOCK | H21: HARVEST | I21: Grow-4 | J21: Grow-2 | K21: Grow-1 | L21: STOCK | M21: HARVEST | N21: Grow-4 | O21: Grow-3 | P21: Grow-2
A23: LEGEND: | B23: STOCK | D23: GROWING | F23: HARVEST
A25: TANK SPECIFICATIONS
A26: Construction | B26: Ferrocement (wire mesh + cement mortar)
A27: Shape | B27: Circular (optimal water circulation)
A28: Diameter | B28: 5 meters
A29: Depth | B29: 1.8 meters (1.5m water depth)
A30: Volume | B30: ~35 m³ per tank
A31: Wall thickness | B31: 50-75mm ferrocement
A32: Foundation | B32: 100mm concrete pad, compacted earth base
A33: Inlet | B33: PVC pipe from reservoir/settling tank
A34: Outlet | B34: Central drain to settling/filtration
A35: Aeration | B35: 1-2 air stones per tank, continuous
A36: Shading | B36: 50% shade cloth canopy (reduces algae + heat stress)
A37: Estimated cost per tank | B37: $400-500 materials + labor
A39: BREEDING PROGRAM
A40: Dedicated breeding tanks | B40: 2 tanks (1 broodstock, 1 nursery)
A41: Broodstock ratio | B41: 1 male : 3 females
A42: Broodstock quantity | B42: 50 females + 17 males
A43: Spawning frequency | B43: Every 4-6 weeks per female
A44: Eggs per spawn | B44: 200-400 per female
A45: Fry survival to fingerling | B45: 60-70%
A46: Fingerlings per month | B46: ~5,000-7,000
A47: Farm requirement per month | B47: ~5,000 fingerlings
A48: Surplus for sale | B48: ~1,000-2,000/month
A49: Fingerling grow-out period | B49: 4-6 weeks (fry to fingerling)
A50: Sex reversal (optional) | B50: Methyltestosterone treatment for all-male batches
...
